Workbook
Name UPDATE: 'Data Sheet'!$E$1

Sheet Financials>

Sheet One Page Profile 
B2: ='Data Sheet'!B1& " - One Page Profile" -> HINDUSTAN UNILEVER LTD - One Page Profile
C4: Hindustan Unilever Limited is India's largest Fast-Moving Consumer Goods (FMCG) company, with a legacy of over 90 years in the Indian market. The company is a subsidiary of Unilever and operates across Home Care, Beauty & Personal Care, and Foods & Refreshment segments. HUL owns several trusted brands that are used by millions of consumers every day. With a strong distribution network and focus on innovation, the company reaches a vast majority of Indian households. HUL is committed to sustainable business practices and aims to make sustainable living commonplace while delivering high-quality products to consumers.
B5: INR(Crs)
B6: Key Financial Metrics | C6: ='Data Sheet'!G16 -> 44286 | D6: ='Data Sheet'!H16 -> 44651 | E6: ='Data Sheet'!I16 -> 45016 | F6: ='Data Sheet'!J16 -> 45382 | G6: ='Data Sheet'!K16 -> 45747 | I6: Share Price - 5Y
B8: Total Sales | C8: ='Data Sheet'!G17 -> 47028 | D8: ='Data Sheet'!H17 -> 52446 | E8: ='Data Sheet'!I17 -> 60580 | F8: ='Data Sheet'!J17 -> 61896 | G8: ='Data Sheet'!K17 -> 63121
B9: Sales Growth (y-o-y) | C9: =HistoricalFS!H13 -> 0.18211296 | D9: =HistoricalFS!I13 -> 0.11520796 | E9: =HistoricalFS!J13 -> 0.15509286 | F9: =HistoricalFS!K13 -> 0.021723341 | G9: =HistoricalFS!L13 -> 0.019791263
B10: Gross Profit Margin(%) | C10: =HistoricalFS!H19 -> 0.46200136 | D10: =HistoricalFS!I19 -> 0.44579186 | E10: =HistoricalFS!J19 -> 0.41596236 | F10: =HistoricalFS!K19 -> 0.45632997 | G10: =HistoricalFS!L19 -> 0.45297128
B11: EBITDA Margins(%) | C11: =HistoricalFS!H25 -> 0.24721443 | D11: =HistoricalFS!I25 -> 0.24514739 | E11: =HistoricalFS!J25 -> 0.23352592 | F11: =HistoricalFS!K25 -> 0.23683275 | G11: =HistoricalFS!L25 -> 0.23515153
B12: EBIT Margins(%) | C12: =(HistoricalFS!H24-HistoricalFS!H30)/HistoricalFS!H12 -> 0.22437697 | D12: =(HistoricalFS!I24-HistoricalFS!I30)/HistoricalFS!I12 -> 0.22434504 | E12: =(HistoricalFS!J24-HistoricalFS!J30)/HistoricalFS!J12 -> 0.21475735 | F12: =(HistoricalFS!K24-HistoricalFS!K30)/HistoricalFS!K12 -> 0.21718689 | G12: =(HistoricalFS!L24-HistoricalFS!L30)/HistoricalFS!L12 -> 0.21368483
B13: Net Profit Margins(%) | C13: =HistoricalFS!H39/HistoricalFS!H12 -> 0.16647529 | D13: =HistoricalFS!I39/HistoricalFS!I12 -> 0.16537009 | E13: =HistoricalFS!J39/HistoricalFS!J12 -> 0.16003632 | F13: =HistoricalFS!K39/HistoricalFS!K12 -> 0.1529178 | G13: =HistoricalFS!L39/HistoricalFS!L12 -> 0.14811236
B14: Earnings Per Share (in Rs.) | C14: =HistoricalFS!H44 -> 33.320565 | D14: =HistoricalFS!I44 -> 36.912666 | E14: =HistoricalFS!J44 -> 41.262343 | F14: =HistoricalFS!K44 -> 40.283453 | G14: =HistoricalFS!L44 -> 39.789751
B15: EPS Growth y-o-y (%) | C15: =HistoricalFS!H45 -> 0.13917182 | D15: =HistoricalFS!I45 -> 0.10780432 | E15: =HistoricalFS!J45 -> 0.11783697 | F15: =HistoricalFS!K45 -> -0.023723569 | G15: =HistoricalFS!L45 -> -0.012255679
B16: Dividend Per Share | C16: =HistoricalFS!H47 -> 40.506895 | D16: =HistoricalFS!I47 -> 34.005788 | E16: =HistoricalFS!J47 -> 39.006639 | F16: =HistoricalFS!K47 -> 42.00715 | G16: =HistoricalFS!L47 -> 53.009023
B17: Dividend Growth y-o-y (%) | C17: =HistoricalFS!H47/HistoricalFS!G47-1 -> 0.6238764 | D17: =HistoricalFS!I47/HistoricalFS!H47-1 -> -0.16049383 | E17: =HistoricalFS!J47/HistoricalFS!I47-1 -> 0.14705882 | F17: =HistoricalFS!K47/HistoricalFS!J47-1 -> 0.076923077 | G17: =HistoricalFS!L47/HistoricalFS!K47-1 -> 0.26190476
B19: Key Financial Ratios | C19: =C6 -> 44286 | D19: =D6 -> 44651 | E19: =E6 -> 45016 | F19: =F6 -> 45382 | G19: =G6 -> 45747 | I19: Volume - 5Y
B21: Price to Earnings | C21: ='Data Sheet'!G90/HistoricalFS!H44 -> 69.840352 | D21: ='Data Sheet'!H90/HistoricalFS!I44 -> 53.117269 | E21: ='Data Sheet'!I90/HistoricalFS!J44 -> 59.386837 | F21: ='Data Sheet'!J90/HistoricalFS!K44 -> 53.797276 | G21: ='Data Sheet'!K90/HistoricalFS!L44 -> 54.332584
B22: EV/EBITDA | C22: =(('Data Sheet'!G93*'Data Sheet'!G90)+(SUM('Data Sheet'!G59:G60))-('Data Sheet'!G69))/'Data Sheet'!G33 -> 47.776044 | D22: =(('Data Sheet'!H93*'Data Sheet'!H90)+(SUM('Data Sheet'!H59:H60))-('Data Sheet'!H69))/'Data Sheet'!H33 -> 36.613724 | E22: =(('Data Sheet'!I93*'Data Sheet'!I90)+(SUM('Data Sheet'!I59:I60))-('Data Sheet'!I69))/'Data Sheet'!I33 -> 40.75284 | F22: =(('Data Sheet'!J93*'Data Sheet'!J90)+(SUM('Data Sheet'!J59:J60))-('Data Sheet'!J69))/'Data Sheet'!J33 -> 34.18675 | G22: =(('Data Sheet'!K93*'Data Sheet'!K90)+(SUM('Data Sheet'!K59:K60))-('Data Sheet'!K69))/'Data Sheet'!K33 -> 32.884986
B23: EV/Sales | C23: =(('Data Sheet'!G93*'Data Sheet'!G90)+(SUM('Data Sheet'!G59:G60))-('Data Sheet'!G69))/'Data Sheet'!G17 -> 11.979568 | D23: =(('Data Sheet'!H93*'Data Sheet'!H90)+(SUM('Data Sheet'!H59:H60))-('Data Sheet'!H69))/'Data Sheet'!H17 -> 9.119572 | E23: =(('Data Sheet'!I93*'Data Sheet'!I90)+(SUM('Data Sheet'!I59:I60))-('Data Sheet'!I69))/'Data Sheet'!I17 -> 9.8027465 | F23: =(('Data Sheet'!J93*'Data Sheet'!J90)+(SUM('Data Sheet'!J59:J60))-('Data Sheet'!J69))/'Data Sheet'!J17 -> 8.5450306 | G23: =(('Data Sheet'!K93*'Data Sheet'!K90)+(SUM('Data Sheet'!K59:K60))-('Data Sheet'!K69))/'Data Sheet'!K17 -> 8.4102331
B24: Price to Book Value | C24: =(('Data Sheet'!G93*'Data Sheet'!G90)/(SUM('Data Sheet'!G57:G58))) -> 11.469147 | D24: =(('Data Sheet'!H93*'Data Sheet'!H90)/(SUM('Data Sheet'!H57:H58))) -> 9.3900669 | E24: =(('Data Sheet'!I93*'Data Sheet'!I90)/(SUM('Data Sheet'!I57:I58))) -> 11.445519 | F24: =(('Data Sheet'!J93*'Data Sheet'!J90)/(SUM('Data Sheet'!J57:J58))) -> 9.9416458 | G24: =(('Data Sheet'!K93*'Data Sheet'!K90)/(SUM('Data Sheet'!K57:K58))) -> 10.28208
B25: Return on Equity (%) | C25: ='Ratio Analysis'!H29 -> 0.16421949 | D25: ='Ratio Analysis'!I29 -> 0.17677993 | E25: ='Ratio Analysis'!J29 -> 0.19272821 | F25: ='Ratio Analysis'!K29 -> 0.18479831 | G25: ='Ratio Analysis'!L29 -> 0.18924335 | H25: ='Ratio Analysis'!M29 -> 0
B26: Return on Capital Employed (%) | C26: ='Ratio Analysis'!H27 -> 0.22133658 | D26: ='Ratio Analysis'!I27 -> 0.23483155 | E26: ='Ratio Analysis'!J27 -> 0.25250859 | F26: ='Ratio Analysis'!K27 -> 0.25507571 | G26: ='Ratio Analysis'!L27 -> 0.26421156
B28: Top 10 Shareholders | C28: ='Hind. Uni Share Price Daily 5y'!C1239 -> N. Shares (In Crs.) | E28: ='Hind. Uni Share Price Daily 5y'!D1239 -> % Holding | F28: ='Hind. Uni Share Price Daily 5y'!E1239 -> Market Value (In Crs.) | I28: Shareholding Pattern
B29: ='Hind. Uni Share Price Daily 5y'!B1240 -> UNILEVER PLC | C29: ='Hind. Uni Share Price Daily 5y'!C1240 -> 111.43701 | E29: ='Hind. Uni Share Price Daily 5y'!D1240 -> 0.4743 | F29: ='Hind. Uni Share Price Daily 5y'!E1240 -> 248727.42
B30: ='Hind. Uni Share Price Daily 5y'!B1241 -> LIFE INSURANCE CORPORATION OF INDIA | C30: ='Hind. Uni Share Price Daily 5y'!C1241 -> 15.743276 | E30: ='Hind. Uni Share Price Daily 5y'!D1241 -> 0.067 | F30: ='Hind. Uni Share Price Daily 5y'!E1241 -> 35138.992
B31: ='Hind. Uni Share Price Daily 5y'!B1242 -> UNILEVER GROUP LIMITED | C31: ='Hind. Uni Share Price Daily 5y'!C1242 -> 10.673946 | E31: ='Hind. Uni Share Price Daily 5y'!D1242 -> 0.0454 | F31: ='Hind. Uni Share Price Daily 5y'!E1242 -> 23824.247
B32: ='Hind. Uni Share Price Daily 5y'!B1243 -> UNILEVER OVERSEAS HOLDINGS AG | C32: ='Hind. Uni Share Price Daily 5y'!C1243 -> 6.878432 | E32: ='Hind. Uni Share Price Daily 5y'!D1243 -> 0.0293 | F32: ='Hind. Uni Share Price Daily 5y'!E1243 -> 15352.66
B33: ='Hind. Uni Share Price Daily 5y'!B1244 -> UNILEVER UK&CN HOLDINGS LIMITED | C33: ='Hind. Uni Share Price Daily 5y'!C1244 -> 6.008625 | E33: ='Hind. Uni Share Price Daily 5y'!D1244 -> 0.0256 | F33: ='Hind. Uni Share Price Daily 5y'!E1244 -> 13411.251
B34: ='Hind. Uni Share Price Daily 5y'!B1245 -> UNILEVER SOUTH INDIA ESTATES LIMITED | C34: ='Hind. Uni Share Price Daily 5y'!C1245 -> 5.27472 | E34: ='Hind. Uni Share Price Daily 5y'!D1245 -> 0.0224 | F34: ='Hind. Uni Share Price Daily 5y'!E1245 -> 11773.175
B35: ='Hind. Uni Share Price Daily 5y'!B1246 -> SBI ESG EXCLUSIONARY STRATEGY FUND | C35: ='Hind. Uni Share Price Daily 5y'!C1246 -> 3.8897573 | E35: ='Hind. Uni Share Price Daily 5y'!D1246 -> 0.0166 | F35: ='Hind. Uni Share Price Daily 5y'!E1246 -> 8681.9383
B36: ='Hind. Uni Share Price Daily 5y'!B1247 -> ICICI PRUDENTIAL SENSEX ETF | C36: ='Hind. Uni Share Price Daily 5y'!C1247 -> 3.4496318 | E36: ='Hind. Uni Share Price Daily 5y'!D1247 -> 0.0147 | F36: ='Hind. Uni Share Price Daily 5y'!E1247 -> 7699.5782
B37: ='Hind. Uni Share Price Daily 5y'!B1248 -> UNILEVER ASSAM ESTATES LIMITED | C37: ='Hind. Uni Share Price Daily 5y'!C1248 -> 3.282048 | E37: ='Hind. Uni Share Price Daily 5y'!D1248 -> 0.014 | F37: ='Hind. Uni Share Price Daily 5y'!E1248 -> 7325.5311
B38: ='Hind. Uni Share Price Daily 5y'!B1249 -> UNILEVER OVERSEAS HOLDINGS B V | C38: ='Hind. Uni Share Price Daily 5y'!C1249 -> 1.8865 | E38: ='Hind. Uni Share Price Daily 5y'!D1249 -> 0.008 | F38: ='Hind. Uni Share Price Daily 5y'!E1249 -> 4210.668
B40: Managerial Remuneration | C40: Deisgnation | E40: Remunertaion (in Crs.) | I40: Capital Structure
B42: Rohit Jawa | C42: CEO & MD | E42: =223923213/10000000 -> 22.392321 | I42: Share Price as on April 2026 | K42: ='Data Sheet'!B8 -> 2082.5
B43: Madhusudhan Rao Rupanagudi | C43: Executive Director (Beauty) | E43: =129413118/10000000 -> 12.941312 | I43: Number of Shares o/s | K43: ='Data Sheet'!B6 -> 234.95918
B44: Ritesh Tiwari | C44: Executive Director (Finance & IT) | E44: =85560788/10000000 -> 8.5560788 | I44: Market Capitalisation | K44: =K42*K43 -> 489302.49
B45: Anuradha Razdan | C45: Executive Director (HR) | E45: =83181617/10000000 -> 8.3181617 | I45: Less : Cash & Equivalents | K45: =-'Data Sheet'!K69 -> -7554
B46: Kedar Lele | C46: Executive Director (Customer Dev.) | E46: =79572021/10000000 -> 7.9572021 | I46: Add : Total Debt | K46: ='Data Sheet'!K59 -> 1648
B47: Deepak Subramanian | C47: Executive Director (Home Care) | E47: =68250477/10000000 -> 6.8250477 | I47: Add : Minority Interest | K47: 22
I48: Enterprise Value | K48: =SUM(K44:K47) -> 483418.49
...

Sheet HistoricalFS
B3: ='Dupont Analysis'!B3 -> HINDUSTAN UNILEVER LTD
B4: ='Dupont Analysis'!B4 -> (HINDUNILVR | BSE Code: 500696)
B6: Historical Financial Statement
B8: ="Historical Financial Statement -"&'Data Sheet'!B1 -> Historical Financial Statement -HINDUSTAN UNILEVER LTD
B9: Years | C9: ='Data Sheet'!B16 -> 42460 | D9: ='Data Sheet'!C16 -> 42825 | E9: ='Data Sheet'!D16 -> 43190 | F9: ='Data Sheet'!E16 -> 43555 | G9: ='Data Sheet'!F16 -> 43921 | H9: ='Data Sheet'!G16 -> 44286 | I9: ='Data Sheet'!H16 -> 44651 | J9: ='Data Sheet'!I16 -> 45016 | ... L9: ='Data Sheet'!K16 -> 45747 | M9: LTM
A11: # | B11: Income Statement
B12: Sales | C12: =IFERROR('Data Sheet'!B17,0) -> 32186 | D12: =IFERROR('Data Sheet'!C17,0) -> 33162 | E12: =IFERROR('Data Sheet'!D17,0) -> 35545 | F12: =IFERROR('Data Sheet'!E17,0) -> 39310 | G12: =IFERROR('Data Sheet'!F17,0) -> 39783 | H12: =IFERROR('Data Sheet'!G17,0) -> 47028 | I12: =IFERROR('Data Sheet'!H17,0) -> 52446 | J12: =IFERROR('Data Sheet'!I17,0) -> 60580 | ... L12: =IFERROR('Data Sheet'!K17,0) -> 63121 | M12: =IFERROR(SUM('Data Sheet'!H42:K42),0) -> 64544
B13: Sales Growth | C13: - | D13: =(D12/C12)-1 -> 0.030323743 | E13: =(E12/D12)-1 -> 0.071859357 | F13: =(F12/E12)-1 -> 0.10592207 | G13: =(G12/F12)-1 -> 0.012032562 | H13: =(H12/G12)-1 -> 0.18211296 | I13: =(I12/H12)-1 -> 0.11520796 | J13: =(J12/I12)-1 -> 0.15509286 | K13: =(K12/J12)-1 -> 0.021723341 | ... M13: =(M12/L12)-1 -> 0.022544003
B15: COGS | C15: =IFERROR(SUM('Data Sheet'!B18,'Data Sheet'!B20:B22)-1*'Data Sheet'!B19,0) -> 18222 | D15: =IFERROR(SUM('Data Sheet'!C18,'Data Sheet'!C20:C22)-1*'Data Sheet'!C19,0) -> 18675 | E15: =IFERROR(SUM('Data Sheet'!D18,'Data Sheet'!D20:D22)-1*'Data Sheet'!D19,0) -> 19314 | F15: =IFERROR(SUM('Data Sheet'!E18,'Data Sheet'!E20:E22)-1*'Data Sheet'!E19,0) -> 21081 | G15: =IFERROR(SUM('Data Sheet'!F18,'Data Sheet'!F20:F22)-1*'Data Sheet'!F19,0) -> 20614 | H15: =IFERROR(SUM('Data Sheet'!G18,'Data Sheet'!G20:G22)-1*'Data Sheet'!G19,0) -> 25301 | I15: =IFERROR(SUM('Data Sheet'!H18,'Data Sheet'!H20:H22)-1*'Data Sheet'!H19,0) -> 29066 | J15: =IFERROR(SUM('Data Sheet'!I18,'Data Sheet'!I20:I22)-1*'Data Sheet'!I19,0) -> 35381 | ... L15: =IFERROR(SUM('Data Sheet'!K18,'Data Sheet'!K20:K22)-1*'Data Sheet'!K19,0) -> 34529 | M15: =IFERROR(SUM('Data Sheet'!H43:K43),0) -> 49646
B16: COGS % Sales | C16: =C15/C12 -> 0.56614677 | D16: =D15/D12 -> 0.56314456 | E16: =E15/E12 -> 0.54336756 | F16: =F15/F12 -> 0.53627576 | G16: =G15/G12 -> 0.51816102 | H16: =H15/H12 -> 0.53799864 | I16: =I15/I12 -> 0.55420814 | J16: =J15/J12 -> 0.58403764 | ... M16: =M15/M12 -> 0.76918071
B18: Gross Profit | C18: =C12-C15 -> 13964 | D18: =D12-D15 -> 14487 | E18: =E12-E15 -> 16231 | F18: =F12-F15 -> 18229 | G18: =G12-G15 -> 19169 | H18: =H12-H15 -> 21727 | I18: =I12-I15 -> 23380 | J18: =J12-J15 -> 25199 | ... M18: =M12-M15 -> 14898
B19: Gross Margin | C19: =IFERROR(C18/C12,0) -> 0.43385323 | D19: =IFERROR(D18/D12,0) -> 0.43685544 | E19: =IFERROR(E18/E12,0) -> 0.45663244 | F19: =IFERROR(F18/F12,0) -> 0.46372424 | G19: =IFERROR(G18/G12,0) -> 0.48183898 | H19: =IFERROR(H18/H12,0) -> 0.46200136 | I19: =IFERROR(I18/I12,0) -> 0.44579186 | J19: =IFERROR(J18/J12,0) -> 0.41596236 | ... M19: =IFERROR(M18/M12,0) -> 0.23081929
B21: Selling & General expenses | C21: =IFERROR(SUM('Data Sheet'!B23:B24),0) -> 8054 | D21: =IFERROR(SUM('Data Sheet'!C23:C24),0) -> 8159 | E21: =IFERROR(SUM('Data Sheet'!D23:D24),0) -> 8732 | F21: =IFERROR(SUM('Data Sheet'!E23:E24),0) -> 9349 | G21: =IFERROR(SUM('Data Sheet'!F23:F24),0) -> 9308 | H21: =IFERROR(SUM('Data Sheet'!G23:G24),0) -> 10101 | I21: =IFERROR(SUM('Data Sheet'!H23:H24),0) -> 10523 | J21: =IFERROR(SUM('Data Sheet'!I23:I24),0) -> 11052 | ... M21: =IFERROR(SUM('Data Sheet'!L23:L24),0) -> 0
B22: S&G Expense % Sales | C22: =C21/C12 -> 0.25023302 | D22: =D21/D12 -> 0.24603462 | E22: =E21/E12 -> 0.24566043 | F22: =F21/F12 -> 0.23782752 | G22: =G21/G12 -> 0.23396928 | H22: =H21/H12 -> 0.21478694 | I22: =I21/I12 -> 0.20064447 | J22: =J21/J12 -> 0.18243645 | ... L22: =L21/L12 -> 0.21781974
B24: EBIDTA | C24: =C18-C21 -> 5910 | D24: =D18-D21 -> 6328 | E24: =E18-E21 -> 7499 | F24: =F18-F21 -> 8880 | G24: =G18-G21 -> 9861 | H24: =H18-H21 -> 11626 | I24: =I18-I21 -> 12857 | J24: =J18-J21 -> 14147 | ... L24: =L18-L21 -> 14843 | M24: =IFERROR(SUM('Data Sheet'!H45:K47),0) -> 19460
B25: EBITDA Margins | C25: =C24/C12 -> 0.18362021 | D25: =D24/D12 -> 0.19082082 | E25: =E24/E12 -> 0.21097201 | F25: =F24/F12 -> 0.22589672 | G25: =G24/G12 -> 0.24786969 | H25: =H24/H12 -> 0.24721443 | I25: =I24/I12 -> 0.24514739 | J25: =J24/J12 -> 0.23352592 | ... M25: =M24/M12 -> 0.30149975
B27: Interest | C27: =IFERROR('Data Sheet'!B27,0) -> 17 | D27: =IFERROR('Data Sheet'!C27,0) -> 35 | E27: =IFERROR('Data Sheet'!D27,0) -> 26 | F27: =IFERROR('Data Sheet'!E27,0) -> 33 | G27: =IFERROR('Data Sheet'!F27,0) -> 118 | H27: =IFERROR('Data Sheet'!G27,0) -> 117 | I27: =IFERROR('Data Sheet'!H27,0) -> 106 | J27: =IFERROR('Data Sheet'!I27,0) -> 114 | ... L27: =IFERROR('Data Sheet'!K27,0) -> 395 | M27: =IFERROR(SUM('Data Sheet'!H46:K46),0) -> 419
B28: Interest % Sales | C28: =C27/C12 -> 0.00052817995 | D28: =D27/D12 -> 0.0010554249 | E28: =E27/E12 -> 0.00073146715 | F28: =F27/F12 -> 0.00083948105 | G28: =G27/G12 -> 0.002966091 | H28: =H27/H12 -> 0.0024878796 | I28: =I27/I12 -> 0.0020211265 | J28: =J27/J12 -> 0.0018818092 | ... M28: =M27/M12 -> 0.0064916956
B30: Depriciation | C30: =IFERROR('Data Sheet'!B26,0) -> 353 | D30: =IFERROR('Data Sheet'!C26,0) -> 432 | E30: =IFERROR('Data Sheet'!D26,0) -> 520 | F30: =IFERROR('Data Sheet'!E26,0) -> 565 | G30: =IFERROR('Data Sheet'!F26,0) -> 1002 | H30: =IFERROR('Data Sheet'!G26,0) -> 1074 | I30: =IFERROR('Data Sheet'!H26,0) -> 1091 | J30: =IFERROR('Data Sheet'!I26,0) -> 1137 | ... L30: =IFERROR('Data Sheet'!K26,0) -> 1355 | M30: =IFERROR(SUM('Data Sheet'!H45:K45),0) -> 1367
B31: Depriciation % Sales | C31: =C30/C12 -> 0.010967501 | D31: =D30/D12 -> 0.013026959 | E31: =E30/E12 -> 0.014629343 | F31: =F30/F12 -> 0.014372933 | G31: =G30/G12 -> 0.025186638 | H31: =H30/H12 -> 0.022837459 | I31: =I30/I12 -> 0.020802349 | J31: =J30/J12 -> 0.01876857 | ... M31: =M30/M12 -> 0.021179351
B33: Earnings Before Tax | C33: =IFERROR(C24-SUM(C27,C30),0) -> 5540 | D33: =IFERROR(D24-SUM(D27,D30),0) -> 5861 | E33: =IFERROR(E24-SUM(E27,E30),0) -> 6953 | F33: =IFERROR(F24-SUM(F27,F30),0) -> 8282 | G33: =IFERROR(G24-SUM(G27,G30),0) -> 8741 | H33: =IFERROR(H24-SUM(H27,H30),0) -> 10435 | I33: =IFERROR(I24-SUM(I27,I30),0) -> 11660 | J33: =IFERROR(J24-SUM(J27,J30),0) -> 12896 | ... M33: =IFERROR(M24-SUM(M27,M30),0) -> 17674
B34: EBT % Sales | C34: =C33/C12 -> 0.17212453 | D34: =D33/D12 -> 0.17673844 | E34: =E33/E12 -> 0.1956112 | F34: =F33/F12 -> 0.2106843 | G34: =G33/G12 -> 0.21971696 | H34: =H33/H12 -> 0.22188909 | I34: =I33/I12 -> 0.22232391 | J34: =J33/J12 -> 0.21287554 | ... M34: =M33/M12 -> 0.27382871
B36: Tax | C36: =IFERROR('Data Sheet'!B29,0) -> 1875 | D36: =IFERROR('Data Sheet'!C29,0) -> 1977 | E36: =IFERROR('Data Sheet'!D29,0) -> 2079 | F36: =IFERROR('Data Sheet'!E29,0) -> 2544 | G36: =IFERROR('Data Sheet'!F29,0) -> 2409 | H36: =IFERROR('Data Sheet'!G29,0) -> 2606 | I36: =IFERROR('Data Sheet'!H29,0) -> 2987 | J36: =IFERROR('Data Sheet'!I29,0) -> 3201 | ... L36: =IFERROR('Data Sheet'!K29,0) -> 3744 | M36: =IFERROR(SUM('Data Sheet'!H48:K48),0) -> 3134
B37: Effective Tax rate | C37: =C36/C33 -> 0.33844765 | D37: =D36/D33 -> 0.33731445 | E37: =E36/E33 -> 0.29900762 | F37: =F36/F33 -> 0.30717218 | G37: =G36/G33 -> 0.27559776 | H37: =H36/H33 -> 0.24973646 | I37: =I36/I33 -> 0.25617496 | J37: =J36/J33 -> 0.2482165 | ... M37: =M36/M33 -> 0.17732262
B39: Net Profit | C39: =IFERROR(C33-C36,0) -> 3665 | D39: =IFERROR(D33-D36,0) -> 3884 | E39: =IFERROR(E33-E36,0) -> 4874 | F39: =IFERROR(F33-F36,0) -> 5738 | G39: =IFERROR(G33-G36,0) -> 6332 | H39: =IFERROR(H33-H36,0) -> 7829 | I39: =IFERROR(I33-I36,0) -> 8673 | J39: =IFERROR(J33-J36,0) -> 9695 | ... M39: =IFERROR(M33-M36,0) -> 14540
B40: Net Margins | C40: =IFERROR(C39/C12,0) -> 0.11386938 | D40: =IFERROR(D39/D12,0) -> 0.11712201 | E40: =IFERROR(E39/E12,0) -> 0.13712196 | F40: =IFERROR(F39/F12,0) -> 0.14596795 | G40: =IFERROR(G39/G12,0) -> 0.15916346 | H40: =IFERROR(H39/H12,0) -> 0.16647529 | I40: =IFERROR(I39/I12,0) -> 0.16537009 | J40: =IFERROR(J39/J12,0) -> 0.16003632 | ... M40: =IFERROR(M39/M12,0) -> 0.22527268
B42: No. of Equity Shares | C42: =IFERROR('Data Sheet'!B93,0) -> 216.39 | D42: =IFERROR('Data Sheet'!C93,0) -> 216.43 | E42: =IFERROR('Data Sheet'!D93,0) -> 216.45 | F42: =IFERROR('Data Sheet'!E93,0) -> 216.47 | G42: =IFERROR('Data Sheet'!F93,0) -> 216.48 | H42: =IFERROR('Data Sheet'!G93,0) -> 234.96 | I42: =IFERROR('Data Sheet'!H93,0) -> 234.96 | J42: =IFERROR('Data Sheet'!I93,0) -> 234.96 | ... L42: =IFERROR('Data Sheet'!K93,0) -> 234.96
B44: Earnings Per Share | C44: =IFERROR(C39/C42,0) -> 16.937012 | D44: =IFERROR(D39/D42,0) -> 17.945756 | E44: =IFERROR(E39/E42,0) -> 22.517903 | F44: =IFERROR(F39/F42,0) -> 26.507137 | G44: =IFERROR(G39/G42,0) -> 29.249815 | H44: =IFERROR(H39/H42,0) -> 33.320565 | I44: =IFERROR(I39/I42,0) -> 36.912666 | J44: =IFERROR(J39/J42,0) -> 41.262343 | ... L44: =IFERROR(L39/L42,0) -> 39.789751
B45: EPS Growth % | D45: =IFERROR((D44/C44)-1,0) -> 0.059558573 | E45: =IFERROR((E44/D44)-1,0) -> 0.25477591 | F45: =IFERROR((F44/E44)-1,0) -> 0.17715836 | G45: =IFERROR((G44/F44)-1,0) -> 0.10346941 | H45: =IFERROR((H44/G44)-1,0) -> 0.13917182 | I45: =IFERROR((I44/H44)-1,0) -> 0.10780432 | J45: =IFERROR((J44/I44)-1,0) -> 0.11783697 | K45: =IFERROR((K44/J44)-1,0) -> -0.023723569 | L45: =IFERROR((L44/K44)-1,0) -> -0.012255679
B47: Dividend Per Share | C47: =IFERROR('Data Sheet'!B31/HistoricalFS!C42,0) -> 15.971163 | D47: =IFERROR('Data Sheet'!C31/HistoricalFS!D42,0) -> 16.966225 | E47: =IFERROR('Data Sheet'!D31/HistoricalFS!E42,0) -> 19.95842 | F47: =IFERROR('Data Sheet'!E31/HistoricalFS!F42,0) -> 21.952234 | G47: =IFERROR('Data Sheet'!F31/HistoricalFS!G42,0) -> 24.944568 | H47: =IFERROR('Data Sheet'!G31/HistoricalFS!H42,0) -> 40.506895 | I47: =IFERROR('Data Sheet'!H31/HistoricalFS!I42,0) -> 34.005788 | J47: =IFERROR('Data Sheet'!I31/HistoricalFS!J42,0) -> 39.006639 | ... L47: =IFERROR('Data Sheet'!K31/HistoricalFS!L42,0) -> 53.009023
B48: Dividend Payout Ratio | C48: =IFERROR(C47/C44,0) -> 0.94297408 | D48: =IFERROR(D47/D44,0) -> 0.9454171 | E48: =IFERROR(E47/E44,0) -> 0.88633566 | F48: =IFERROR(F47/F44,0) -> 0.82816312 | G48: =IFERROR(G47/G44,0) -> 0.85281112 | H48: =IFERROR(H47/H44,0) -> 1.2156725 | I48: =IFERROR(I47/I44,0) -> 0.92124986 | J48: =IFERROR(J47/J44,0) -> 0.94533265 | ... L48: =IFERROR(L47/L44,0) -> 1.332228
B50: Retained Earnings | C50: =IFERROR(1-C48,0) -> 0.057025921 | D50: =IFERROR(1-D48,0) -> 0.054582904 | E50: =IFERROR(1-E48,0) -> 0.11366434 | F50: =IFERROR(1-F48,0) -> 0.17183688 | G50: =IFERROR(1-G48,0) -> 0.14718888 | H50: =IFERROR(1-H48,0) -> -0.2156725 | I50: =IFERROR(1-I48,0) -> 0.078750144 | J50: =IFERROR(1-J48,0) -> 0.054667354 | ... L50: =IFERROR(1-L48,0) -> -0.33222805
A52: # | B52: Balance Sheet
B53: Equity Share Capital | C53: =IFERROR('Data Sheet'!B57,0) -> 216 | D53: =IFERROR('Data Sheet'!C57,0) -> 216 | E53: =IFERROR('Data Sheet'!D57,0) -> 216 | F53: =IFERROR('Data Sheet'!E57,0) -> 216 | G53: =IFERROR('Data Sheet'!F57,0) -> 216 | H53: =IFERROR('Data Sheet'!G57,0) -> 235 | I53: =IFERROR('Data Sheet'!H57,0) -> 235 | J53: =IFERROR('Data Sheet'!I57,0) -> 235 | ... L53: =IFERROR('Data Sheet'!K57,0) -> 235
B54: Reserves | C54: =IFERROR('Data Sheet'!B58,0) -> 6357 | D54: =IFERROR('Data Sheet'!C58,0) -> 6528 | E54: =IFERROR('Data Sheet'!D58,0) -> 7065 | F54: =IFERROR('Data Sheet'!E58,0) -> 7651 | G54: =IFERROR('Data Sheet'!F58,0) -> 8013 | H54: =IFERROR('Data Sheet'!G58,0) -> 47439 | I54: =IFERROR('Data Sheet'!H58,0) -> 48826 | J54: =IFERROR('Data Sheet'!I58,0) -> 50069 | ... L54: =IFERROR('Data Sheet'!K58,0) -> 49167
B55: Borrowings | C55: =IFERROR('Data Sheet'!B59,0) -> 177 | D55: =IFERROR('Data Sheet'!C59,0) -> 277 | E55: =IFERROR('Data Sheet'!D59,0) -> 0 | F55: =IFERROR('Data Sheet'!E59,0) -> 99 | G55: =IFERROR('Data Sheet'!F59,0) -> 0 | H55: =IFERROR('Data Sheet'!G59,0) -> 0 | I55: =IFERROR('Data Sheet'!H59,0) -> 1043 | J55: =IFERROR('Data Sheet'!I59,0) -> 1219 | ... L55: =IFERROR('Data Sheet'!K59,0) -> 1648
B56: Other Liabilities | C56: =IFERROR('Data Sheet'!B60,0) -> 8043 | D56: =IFERROR('Data Sheet'!C60,0) -> 8685 | E56: =IFERROR('Data Sheet'!D60,0) -> 10581 | F56: =IFERROR('Data Sheet'!E60,0) -> 10663 | G56: =IFERROR('Data Sheet'!F60,0) -> 11924 | H56: =IFERROR('Data Sheet'!G60,0) -> 21066 | I56: =IFERROR('Data Sheet'!H60,0) -> 20402 | J56: =IFERROR('Data Sheet'!I60,0) -> 21554 | ... L56: =IFERROR('Data Sheet'!K60,0) -> 28813
B57: Total Liabilities | C57: =IFERROR('Data Sheet'!B61,0) -> 14793 | D57: =IFERROR('Data Sheet'!C61,0) -> 15706 | E57: =IFERROR('Data Sheet'!D61,0) -> 17862 | F57: =IFERROR('Data Sheet'!E61,0) -> 18629 | G57: =IFERROR('Data Sheet'!F61,0) -> 20153 | H57: =IFERROR('Data Sheet'!G61,0) -> 68740 | I57: =IFERROR('Data Sheet'!H61,0) -> 70506 | J57: =IFERROR('Data Sheet'!I61,0) -> 73077 | ... L57: =IFERROR('Data Sheet'!K61,0) -> 79863
B59: Fixed Assets Net Block | C59: =IFERROR('Data Sheet'!B62,0) -> 3258 | D59: =IFERROR('Data Sheet'!C62,0) -> 4419 | E59: =IFERROR('Data Sheet'!D62,0) -> 4528 | F59: =IFERROR('Data Sheet'!E62,0) -> 4715 | G59: =IFERROR('Data Sheet'!F62,0) -> 5479 | H59: =IFERROR('Data Sheet'!G62,0) -> 51443 | I59: =IFERROR('Data Sheet'!H62,0) -> 51473 | J59: =IFERROR('Data Sheet'!I62,0) -> 52678 | ... L59: =IFERROR('Data Sheet'!K62,0) -> 54335
B60: Capital Work in Progress | C60: =IFERROR('Data Sheet'!B63,0) -> 408 | D60: =IFERROR('Data Sheet'!C63,0) -> 229 | E60: =IFERROR('Data Sheet'!D63,0) -> 461 | F60: =IFERROR('Data Sheet'!E63,0) -> 406 | G60: =IFERROR('Data Sheet'!F63,0) -> 597 | H60: =IFERROR('Data Sheet'!G63,0) -> 745 | I60: =IFERROR('Data Sheet'!H63,0) -> 1313 | J60: =IFERROR('Data Sheet'!I63,0) -> 1132 | ... L60: =IFERROR('Data Sheet'!K63,0) -> 1009
...

Sheet Forecast
B3: {=HistoricalFS!B3:B4} -> HINDUSTAN UNILEVER LTD
B4: (HINDUNILVR | BSE Code: 500696)
B6: Forecasting
B8: ='Data Sheet'!B1& " - "&'Data Sheet'!A17 &" " & "Forecasting" -> HINDUSTAN UNILEVER LTD - Sales Forecasting | G8: ='Data Sheet'!B1& " - "& HistoricalFS!B24 &" " & "Forecasting" -> HINDUSTAN UNILEVER LTD - EBIDTA Forecasting | L8: ='Data Sheet'!B1& " - "& HistoricalFS!B44 &"Forecasting" -> HINDUSTAN UNILEVER LTD - Earnings Per Share Forecasting
B9: Year Weight | C9: Year | D9: Sales | E9: Sales as Growth | G9: Year Weight | H9: Year | I9: =HistoricalFS!B24 -> EBIDTA | J9: EBIDTA as Growth | L9: Year Weight | M9: Year | N9: =HistoricalFS!B44 -> Earnings Per Share | O9: EPS as Growth
B10: 1 | C10: ='Data Sheet'!$B$16 -> 42460 | D10: {=TRANSPOSE('Data Sheet'!B17:K17)} -> 32186 | G10: 1 | H10: ='Data Sheet'!$B$16 -> 42460 | I10: {=TRANSPOSE(HistoricalFS!C24:L24)} -> 5910 | L10: 1 | M10: ='Data Sheet'!$B$16 -> 42460 | N10: {=TRANSPOSE(HistoricalFS!C44:L44)} -> 16.937012
B11: =B10+1 -> 2 | C11: =C10+365 -> 42825 | D11: 33162 | E11: =(D11/D10)-1 -> 0.030323743 | G11: =G10+1 -> 2 | H11: =H10+365 -> 42825 | I11: 6328 | J11: =(I11/I10)-1 -> 0.07072758 | L11: =L10+1 -> 2 | M11: =M10+365 -> 42825 | N11: 17.945756 | O11: =(N11/N10)-1 -> 0.059558573
B12: =B11+1 -> 3 | C12: =C11+365 -> 43190 | D12: 35545 | E12: =(D12/D11)-1 -> 0.071859357 | G12: =G11+1 -> 3 | H12: =H11+365 -> 43190 | I12: 7499 | J12: =(I12/I11)-1 -> 0.18505057 | L12: =L11+1 -> 3 | M12: =M11+365 -> 43190 | N12: 22.517903 | O12: =(N12/N11)-1 -> 0.25477591
B13: =B12+1 -> 4 | C13: =C12+365 -> 43555 | D13: 39310 | E13: =(D13/D12)-1 -> 0.10592207 | G13: =G12+1 -> 4 | H13: =H12+365 -> 43555 | I13: 8880 | J13: =(I13/I12)-1 -> 0.18415789 | L13: =L12+1 -> 4 | M13: =M12+365 -> 43555 | N13: 26.507137 | O13: =(N13/N12)-1 -> 0.17715836
B14: =B13+1 -> 5 | C14: =C13+365 -> 43920 | D14: 39783 | E14: =(D14/D13)-1 -> 0.012032562 | G14: =G13+1 -> 5 | H14: =H13+365 -> 43920 | I14: 9861 | J14: =(I14/I13)-1 -> 0.11047297 | L14: =L13+1 -> 5 | M14: =M13+365 -> 43920 | N14: 29.249815 | O14: =(N14/N13)-1 -> 0.10346941
B15: =B14+1 -> 6 | C15: =C14+365 -> 44285 | D15: 47028 | E15: =(D15/D14)-1 -> 0.18211296 | G15: =G14+1 -> 6 | H15: =H14+365 -> 44285 | I15: 11626 | J15: =(I15/I14)-1 -> 0.17898793 | L15: =L14+1 -> 6 | M15: =M14+365 -> 44285 | N15: 33.320565 | O15: =(N15/N14)-1 -> 0.13917182
B16: =B15+1 -> 7 | C16: =C15+365 -> 44650 | D16: 52446 | E16: =(D16/D15)-1 -> 0.11520796 | G16: =G15+1 -> 7 | H16: =H15+365 -> 44650 | I16: 12857 | J16: =(I16/I15)-1 -> 0.10588336 | L16: =L15+1 -> 7 | M16: =M15+365 -> 44650 | N16: 36.912666 | O16: =(N16/N15)-1 -> 0.10780432
B17: =B16+1 -> 8 | C17: =C16+365 -> 45015 | D17: 60580 | E17: =(D17/D16)-1 -> 0.15509286 | G17: =G16+1 -> 8 | H17: =H16+365 -> 45015 | I17: 14147 | J17: =(I17/I16)-1 -> 0.10033445 | L17: =L16+1 -> 8 | M17: =M16+365 -> 45015 | N17: 41.262343 | O17: =(N17/N16)-1 -> 0.11783697
B18: =B17+1 -> 9 | C18: =C17+365 -> 45380 | D18: 61896 | E18: =(D18/D17)-1 -> 0.021723341 | G18: =G17+1 -> 9 | H18: =H17+365 -> 45380 | I18: 14659 | J18: =(I18/I17)-1 -> 0.036191419 | L18: =L17+1 -> 9 | M18: =M17+365 -> 45380 | N18: 40.283453 | O18: =(N18/N17)-1 -> -0.023723569
B19: =B18+1 -> 10 | C19: =C18+365 -> 45745 | D19: 63121 | E19: =(D19/D18)-1 -> 0.019791263 | G19: =G18+1 -> 10 | H19: =H18+365 -> 45745 | I19: 14843 | J19: =(I19/I18)-1 -> 0.012552016 | L19: =L18+1 -> 10 | M19: =M18+365 -> 45745 | N19: 39.789751 | O19: =(N19/N18)-1 -> -0.012255679
B20: =B19+1 -> 11 | C20: =C19+365 -> 46110 | D20: =FORECAST(B20,$D$10:$D$19,$B$10:$B$19) -> 68218.4 | E20: =(D20/D19)-1 -> 0.080756008 | G20: =G19+1 -> 11 | H20: =H19+365 -> 46110 | I20: =FORECAST(G20,$I$10:$I$19,$G$10:$G$19) -> 16849.333 | J20: =(I20/I19)-1 -> 0.13517034 | L20: =L19+1 -> 11 | M20: =M19+365 -> 46110 | N20: =FORECAST(L20,$N$10:$N$19,$L$10:$L$19) -> 46.840909 | O20: =(N20/N19)-1 -> 0.17721039
B21: =B20+1 -> 12 | C21: =C20+365 -> 46475 | D21: =FORECAST(B21,$D$10:$D$19,$B$10:$B$19) -> 72166.164 | E21: =(D21/D20)-1 -> 0.057869484 | G21: =G20+1 -> 12 | H21: =H20+365 -> 46475 | I21: =FORECAST(G21,$I$10:$I$19,$G$10:$G$19) -> 17974.485 | J21: =(I21/I20)-1 -> 0.066777213 | L21: =L20+1 -> 12 | M21: =M20+365 -> 46475 | N21: =FORECAST(L21,$N$10:$N$19,$L$10:$L$19) -> 49.816958 | O21: =(N21/N20)-1 -> 0.063535251
B22: =B21+1 -> 13 | C22: =C21+365 -> 46840 | D22: =FORECAST(B22,$D$10:$D$19,$B$10:$B$19) -> 76113.927 | E22: =(D22/D21)-1 -> 0.054703804 | G22: =G21+1 -> 13 | H22: =H21+365 -> 46840 | I22: =FORECAST(G22,$I$10:$I$19,$G$10:$G$19) -> 19099.636 | J22: =(I22/I21)-1 -> 0.062597149 | L22: =L21+1 -> 13 | M22: =M21+365 -> 46840 | N22: =FORECAST(L22,$N$10:$N$19,$L$10:$L$19) -> 52.793007 | O22: =(N22/N21)-1 -> 0.059739675
B23: =B22+1 -> 14 | C23: =C22+365 -> 47205 | D23: =FORECAST(B23,$D$10:$D$19,$B$10:$B$19) -> 80061.691 | E23: =(D23/D22)-1 -> 0.051866508 | G23: =G22+1 -> 14 | H23: =H22+365 -> 47205 | I23: =FORECAST(G23,$I$10:$I$19,$G$10:$G$19) -> 20224.788 | J23: =(I23/I22)-1 -> 0.058909578 | L23: =L22+1 -> 14 | M23: =M22+365 -> 47205 | N23: =FORECAST(L23,$N$10:$N$19,$L$10:$L$19) -> 55.769056 | O23: =(N23/N22)-1 -> 0.056372029
B24: =B23+1 -> 15 | C24: =C23+365 -> 47570 | D24: =FORECAST(B24,$D$10:$D$19,$B$10:$B$19) -> 84009.455 | E24: =(D24/D23)-1 -> 0.049309021 | G24: =G23+1 -> 15 | H24: =H23+365 -> 47570 | I24: =FORECAST(G24,$I$10:$I$19,$G$10:$G$19) -> 21349.939 | J24: =(I24/I23)-1 -> 0.055632302 | L24: =L23+1 -> 15 | M24: =M23+365 -> 47570 | N24: =FORECAST(L24,$N$10:$N$19,$L$10:$L$19) -> 58.745105 | O24: =(N24/N23)-1 -> 0.053363803

Sheet Common Size Income Statement
B3: ='Ratio Analysis'!B3 -> HINDUSTAN UNILEVER LTD
B4: ='Ratio Analysis'!B4 -> (HINDUNILVR | BSE Code: 500696)
B6: Common Size Statement
B8: ="Common Size Income Statement"&" "&"-"&'Data Sheet'!$B$1 -> Common Size Income Statement -HINDUSTAN UNILEVER LTD
B10: Particulars | C10: ='Data Sheet'!B16 -> 42460 | D10: ='Data Sheet'!C16 -> 42825 | E10: ='Data Sheet'!D16 -> 43190 | F10: ='Data Sheet'!E16 -> 43555 | G10: ='Data Sheet'!F16 -> 43921 | H10: ='Data Sheet'!G16 -> 44286 | I10: ='Data Sheet'!H16 -> 44651 | J10: ='Data Sheet'!I16 -> 45016 | ... L10: ='Data Sheet'!K16 -> 45747
B12: ='Data Sheet'!A17 -> Sales | C12: ='Data Sheet'!B17/'Data Sheet'!B$17 -> 1 | D12: ='Data Sheet'!C17/'Data Sheet'!C$17 -> 1 | E12: ='Data Sheet'!D17/'Data Sheet'!D$17 -> 1 | F12: ='Data Sheet'!E17/'Data Sheet'!E$17 -> 1 | G12: ='Data Sheet'!F17/'Data Sheet'!F$17 -> 1 | H12: ='Data Sheet'!G17/'Data Sheet'!G$17 -> 1 | I12: ='Data Sheet'!H17/'Data Sheet'!H$17 -> 1 | J12: ='Data Sheet'!I17/'Data Sheet'!I$17 -> 1 | ... L12: ='Data Sheet'!K17/'Data Sheet'!K$17 -> 1
B13: ='Data Sheet'!A18 -> Raw Material Cost | C13: ='Data Sheet'!B18/'Data Sheet'!B$17 -> 0.40961909 | D13: ='Data Sheet'!C18/'Data Sheet'!C$17 -> 0.41028888 | E13: ='Data Sheet'!D18/'Data Sheet'!D$17 -> 0.400422 | F13: ='Data Sheet'!E18/'Data Sheet'!E$17 -> 0.4030781 | G13: ='Data Sheet'!F18/'Data Sheet'!F$17 -> 0.39456552 | H13: ='Data Sheet'!G18/'Data Sheet'!G$17 -> 0.42827677 | I13: ='Data Sheet'!H18/'Data Sheet'!H$17 -> 0.43608664 | J13: ='Data Sheet'!I18/'Data Sheet'!I$17 -> 0.46924728 | ... L13: ='Data Sheet'!K18/'Data Sheet'!K$17 -> 0.43319973
B14: ='Data Sheet'!A19 -> Change in Inventory | C14: ='Data Sheet'!B19/'Data Sheet'!B$17 -> -0.002578761 | D14: ='Data Sheet'!C19/'Data Sheet'!C$17 -> -0.0043423195 | E14: ='Data Sheet'!D19/'Data Sheet'!D$17 -> 0.0020256014 | F14: ='Data Sheet'!E19/'Data Sheet'!E$17 -> -0.00030526584 | G14: ='Data Sheet'!F19/'Data Sheet'!F$17 -> 0.0027147274 | H14: ='Data Sheet'!G19/'Data Sheet'!G$17 -> 0.0086118908 | I14: ='Data Sheet'!H19/'Data Sheet'!H$17 -> 0.00041947908 | J14: ='Data Sheet'!I19/'Data Sheet'!I$17 -> 0.0012380324 | ... L14: ='Data Sheet'!K19/'Data Sheet'!K$17 -> 0.002423916
B15: ='Data Sheet'!A20 -> Power and Fuel | C15: ='Data Sheet'!B20/'Data Sheet'!B$17 -> 0.0096004474 | D15: ='Data Sheet'!C20/'Data Sheet'!C$17 -> 0.008895724 | E15: ='Data Sheet'!D20/'Data Sheet'!D$17 -> 0.0082993389 | F15: ='Data Sheet'!E20/'Data Sheet'!E$17 -> 0.0078351564 | G15: ='Data Sheet'!F20/'Data Sheet'!F$17 -> 0.0075157731 | H15: ='Data Sheet'!G20/'Data Sheet'!G$17 -> 0.0072084715 | I15: ='Data Sheet'!H20/'Data Sheet'!H$17 -> 0.0060633795 | J15: ='Data Sheet'!I20/'Data Sheet'!I$17 -> 0.0063387257 | ... L15: ='Data Sheet'!K20/'Data Sheet'!K$17 -> 0.0067647851
B16: ='Data Sheet'!A21 -> Other Mfr. Exp | C16: ='Data Sheet'!B21/'Data Sheet'!B$17 -> 0.092151867 | D16: ='Data Sheet'!C21/'Data Sheet'!C$17 -> 0.087057475 | E16: ='Data Sheet'!D21/'Data Sheet'!D$17 -> 0.08434379 | F16: ='Data Sheet'!E21/'Data Sheet'!E$17 -> 0.077359451 | G16: ='Data Sheet'!F21/'Data Sheet'!F$17 -> 0.073046276 | H16: ='Data Sheet'!G21/'Data Sheet'!G$17 -> 0.060984945 | I16: ='Data Sheet'!H21/'Data Sheet'!H$17 -> 0.063951493 | J16: ='Data Sheet'!I21/'Data Sheet'!I$17 -> 0.062578409 | ... L16: ='Data Sheet'!K21/'Data Sheet'!K$17 -> 0.060740483
B17: ='Data Sheet'!A22 -> Employee Cost | C17: ='Data Sheet'!B22/'Data Sheet'!B$17 -> 0.052196607 | D17: ='Data Sheet'!C22/'Data Sheet'!C$17 -> 0.052560159 | E17: ='Data Sheet'!D22/'Data Sheet'!D$17 -> 0.052328035 | F17: ='Data Sheet'!E22/'Data Sheet'!E$17 -> 0.047697787 | G17: ='Data Sheet'!F22/'Data Sheet'!F$17 -> 0.045748184 | H17: ='Data Sheet'!G22/'Data Sheet'!G$17 -> 0.050140342 | I17: ='Data Sheet'!H22/'Data Sheet'!H$17 -> 0.048526103 | J17: ='Data Sheet'!I22/'Data Sheet'!I$17 -> 0.047111258 | ... L17: ='Data Sheet'!K22/'Data Sheet'!K$17 -> 0.048747643
B18: ='Data Sheet'!A23 -> Selling and admin | C18: ='Data Sheet'!B23/'Data Sheet'!B$17 -> 0.20943889 | D18: ='Data Sheet'!C23/'Data Sheet'!C$17 -> 0.20170677 | E18: ='Data Sheet'!D23/'Data Sheet'!D$17 -> 0.20402307 | F18: ='Data Sheet'!E23/'Data Sheet'!E$17 -> 0.19832104 | G18: ='Data Sheet'!F23/'Data Sheet'!F$17 -> 0.1915391 | H18: ='Data Sheet'!G23/'Data Sheet'!G$17 -> 0.16811261 | I18: ='Data Sheet'!H23/'Data Sheet'!H$17 -> 0.15566487 | J18: ='Data Sheet'!I23/'Data Sheet'!I$17 -> 0.14501486 | ... L18: ='Data Sheet'!K23/'Data Sheet'!K$17 -> 0.16940479
B19: ='Data Sheet'!A24 -> Other Expenses | C19: ='Data Sheet'!B24/'Data Sheet'!B$17 -> 0.040794134 | D19: ='Data Sheet'!C24/'Data Sheet'!C$17 -> 0.044327845 | E19: ='Data Sheet'!D24/'Data Sheet'!D$17 -> 0.041637361 | F19: ='Data Sheet'!E24/'Data Sheet'!E$17 -> 0.039506487 | G19: ='Data Sheet'!F24/'Data Sheet'!F$17 -> 0.042430184 | H19: ='Data Sheet'!G24/'Data Sheet'!G$17 -> 0.046674322 | I19: ='Data Sheet'!H24/'Data Sheet'!H$17 -> 0.044979598 | J19: ='Data Sheet'!I24/'Data Sheet'!I$17 -> 0.037421591 | ... L19: ='Data Sheet'!K24/'Data Sheet'!K$17 -> 0.048414949
B20: ='Data Sheet'!A25 -> Other Income | C20: ='Data Sheet'!B25/'Data Sheet'!B$17 -> 0.015099733 | D20: ='Data Sheet'!C25/'Data Sheet'!C$17 -> 0.018273928 | E20: ='Data Sheet'!D25/'Data Sheet'!D$17 -> 0.0099310733 | F20: ='Data Sheet'!E25/'Data Sheet'!E$17 -> 0.0081912999 | G20: ='Data Sheet'!F25/'Data Sheet'!F$17 -> 0.010657819 | H20: ='Data Sheet'!G25/'Data Sheet'!G$17 -> 0.0036148677 | I20: ='Data Sheet'!H25/'Data Sheet'!H$17 -> 0.0041757236 | J20: ='Data Sheet'!I25/'Data Sheet'!I$17 -> 0.0073951799 | ... L20: ='Data Sheet'!K25/'Data Sheet'!K$17 -> 0.020943901
B21: ='Data Sheet'!A26 -> Depreciation | C21: ='Data Sheet'!B26/'Data Sheet'!B$17 -> 0.010967501 | D21: ='Data Sheet'!C26/'Data Sheet'!C$17 -> 0.013026959 | E21: ='Data Sheet'!D26/'Data Sheet'!D$17 -> 0.014629343 | F21: ='Data Sheet'!E26/'Data Sheet'!E$17 -> 0.014372933 | G21: ='Data Sheet'!F26/'Data Sheet'!F$17 -> 0.025186638 | H21: ='Data Sheet'!G26/'Data Sheet'!G$17 -> 0.022837459 | I21: ='Data Sheet'!H26/'Data Sheet'!H$17 -> 0.020802349 | J21: ='Data Sheet'!I26/'Data Sheet'!I$17 -> 0.01876857 | ... L21: ='Data Sheet'!K26/'Data Sheet'!K$17 -> 0.021466707
B22: ='Data Sheet'!A27 -> Interest | C22: ='Data Sheet'!B27/'Data Sheet'!B$17 -> 0.00052817995 | D22: ='Data Sheet'!C27/'Data Sheet'!C$17 -> 0.0010554249 | E22: ='Data Sheet'!D27/'Data Sheet'!D$17 -> 0.00073146715 | F22: ='Data Sheet'!E27/'Data Sheet'!E$17 -> 0.00083948105 | G22: ='Data Sheet'!F27/'Data Sheet'!F$17 -> 0.002966091 | H22: ='Data Sheet'!G27/'Data Sheet'!G$17 -> 0.0024878796 | I22: ='Data Sheet'!H27/'Data Sheet'!H$17 -> 0.0020211265 | J22: ='Data Sheet'!I27/'Data Sheet'!I$17 -> 0.0018818092 | ... L22: ='Data Sheet'!K27/'Data Sheet'!K$17 -> 0.0062578223
B23: ='Data Sheet'!A28 -> Profit before tax | C23: ='Data Sheet'!B28/'Data Sheet'!B$17 -> 0.18722426 | D23: ='Data Sheet'!C28/'Data Sheet'!C$17 -> 0.19501236 | E23: ='Data Sheet'!D28/'Data Sheet'!D$17 -> 0.20554227 | F23: ='Data Sheet'!E28/'Data Sheet'!E$17 -> 0.2188756 | G23: ='Data Sheet'!F28/'Data Sheet'!F$17 -> 0.23037478 | H23: ='Data Sheet'!G28/'Data Sheet'!G$17 -> 0.22550396 | I23: ='Data Sheet'!H28/'Data Sheet'!H$17 -> 0.22649964 | J23: ='Data Sheet'!I28/'Data Sheet'!I$17 -> 0.22027072 | ... L23: ='Data Sheet'!K28/'Data Sheet'!K$17 -> 0.22837091
... B26: ='Data Sheet'!A31 -> Dividend Amount | C26: ='Data Sheet'!B31/'Data Sheet'!B$17 -> 0.10737588 | D26: ='Data Sheet'!C31/'Data Sheet'!C$17 -> 0.11072915 | E26: ='Data Sheet'!D31/'Data Sheet'!D$17 -> 0.12153608 | F26: ='Data Sheet'!E31/'Data Sheet'!E$17 -> 0.12088527 | G26: ='Data Sheet'!F31/'Data Sheet'!F$17 -> 0.13573637 | H26: ='Data Sheet'!G31/'Data Sheet'!G$17 -> 0.20237943 | I26: ='Data Sheet'!H31/'Data Sheet'!H$17 -> 0.15234718 | J26: ='Data Sheet'!I31/'Data Sheet'!I$17 -> 0.15128755 | ... L26: ='Data Sheet'!K31/'Data Sheet'!K$17 -> 0.19731943
B27: ='Data Sheet'!A33 -> EBIDTA | C27: ='Data Sheet'!B33/'Data Sheet'!B$17 -> 0.19871994 | D27: ='Data Sheet'!C33/'Data Sheet'!C$17 -> 0.20867258 | E27: ='Data Sheet'!D33/'Data Sheet'!D$17 -> 0.22053735 | F27: ='Data Sheet'!E33/'Data Sheet'!E$17 -> 0.23393539 | G27: ='Data Sheet'!F33/'Data Sheet'!F$17 -> 0.25832642 | H27: ='Data Sheet'!G33/'Data Sheet'!G$17 -> 0.25074424 | I27: ='Data Sheet'!H33/'Data Sheet'!H$17 -> 0.24907524 | J27: ='Data Sheet'!I33/'Data Sheet'!I$17 -> 0.24054143 | ... L27: ='Data Sheet'!K33/'Data Sheet'!K$17 -> 0.2557469
B29: ="Common Size Balance Sheet"&" "&"-"&'Data Sheet'!$B$1 -> Common Size Balance Sheet -HINDUSTAN UNILEVER LTD
B31: Particulars | C31: ='Data Sheet'!B56 -> 42460 | D31: ='Data Sheet'!C56 -> 42825 | E31: ='Data Sheet'!D56 -> 43190 | F31: ='Data Sheet'!E56 -> 43555 | G31: ='Data Sheet'!F56 -> 43921 | H31: ='Data Sheet'!G56 -> 44286 | I31: ='Data Sheet'!H56 -> 44651 | J31: ='Data Sheet'!I56 -> 45016 | ... L31: ='Data Sheet'!K56 -> 45747
B33: Total Liabilities | C33: ='Data Sheet'!B61/'Data Sheet'!B$61 -> 1 | D33: ='Data Sheet'!C61/'Data Sheet'!C$61 -> 1 | E33: ='Data Sheet'!D61/'Data Sheet'!D$61 -> 1 | F33: ='Data Sheet'!E61/'Data Sheet'!E$61 -> 1 | G33: ='Data Sheet'!F61/'Data Sheet'!F$61 -> 1 | H33: ='Data Sheet'!G61/'Data Sheet'!G$61 -> 1 | I33: ='Data Sheet'!H61/'Data Sheet'!H$61 -> 1 | J33: ='Data Sheet'!I61/'Data Sheet'!I$61 -> 1 | ... L33: ='Data Sheet'!K61/'Data Sheet'!K$61 -> 1
B34: ='Data Sheet'!A57 -> Equity Share Capital | C34: ='Data Sheet'!B57/'Data Sheet'!B$61 -> 0.014601501 | D34: ='Data Sheet'!C57/'Data Sheet'!C$61 -> 0.013752706 | E34: ='Data Sheet'!D57/'Data Sheet'!D$61 -> 0.012092711 | F34: ='Data Sheet'!E57/'Data Sheet'!E$61 -> 0.011594825 | G34: ='Data Sheet'!F57/'Data Sheet'!F$61 -> 0.010718007 | H34: ='Data Sheet'!G57/'Data Sheet'!G$61 -> 0.0034186791 | I34: ='Data Sheet'!H57/'Data Sheet'!H$61 -> 0.0033330497 | J34: ='Data Sheet'!I57/'Data Sheet'!I$61 -> 0.0032157861 | ... L34: ='Data Sheet'!K57/'Data Sheet'!K$61 -> 0.0029425391
B35: ='Data Sheet'!A58 -> Reserves | C35: ='Data Sheet'!B58/'Data Sheet'!B$61 -> 0.42973028 | D35: ='Data Sheet'!C58/'Data Sheet'!C$61 -> 0.41563734 | E35: ='Data Sheet'!D58/'Data Sheet'!D$61 -> 0.39553242 | F35: ='Data Sheet'!E58/'Data Sheet'!E$61 -> 0.41070374 | G35: ='Data Sheet'!F58/'Data Sheet'!F$61 -> 0.3976083 | H35: ='Data Sheet'!G58/'Data Sheet'!G$61 -> 0.6901222 | I35: ='Data Sheet'!H58/'Data Sheet'!H$61 -> 0.69250844 | J35: ='Data Sheet'!I58/'Data Sheet'!I$61 -> 0.68515402 | ... L35: ='Data Sheet'!K58/'Data Sheet'!K$61 -> 0.61564179
B36: ='Data Sheet'!A59 -> Borrowings | C36: ='Data Sheet'!B59/'Data Sheet'!B$61 -> 0.011965119 | D36: ='Data Sheet'!C59/'Data Sheet'!C$61 -> 0.017636572 | E36: ='Data Sheet'!D59/'Data Sheet'!D$61 -> 0 | F36: ='Data Sheet'!E59/'Data Sheet'!E$61 -> 0.0053142949 | G36: ='Data Sheet'!F59/'Data Sheet'!F$61 -> 0 | H36: ='Data Sheet'!G59/'Data Sheet'!G$61 -> 0 | I36: ='Data Sheet'!H59/'Data Sheet'!H$61 -> 0.014793067 | J36: ='Data Sheet'!I59/'Data Sheet'!I$61 -> 0.016681035 | ... L36: ='Data Sheet'!K59/'Data Sheet'!K$61 -> 0.020635338
B37: ='Data Sheet'!A60 -> Other Liabilities | C37: ='Data Sheet'!B60/'Data Sheet'!B$61 -> 0.5437031 | D37: ='Data Sheet'!C60/'Data Sheet'!C$61 -> 0.55297339 | E37: ='Data Sheet'!D60/'Data Sheet'!D$61 -> 0.59237487 | F37: ='Data Sheet'!E60/'Data Sheet'!E$61 -> 0.57238714 | G37: ='Data Sheet'!F60/'Data Sheet'!F$61 -> 0.5916737 | H37: ='Data Sheet'!G60/'Data Sheet'!G$61 -> 0.30645912 | I37: ='Data Sheet'!H60/'Data Sheet'!H$61 -> 0.28936544 | J37: ='Data Sheet'!I60/'Data Sheet'!I$61 -> 0.29494916 | ... L37: ='Data Sheet'!K60/'Data Sheet'!K$61 -> 0.36078034
B39: Total Assets | C39: ='Data Sheet'!B75/'Data Sheet'!B$75 -> 1 | D39: ='Data Sheet'!C75/'Data Sheet'!C$75 -> 1 | E39: ='Data Sheet'!D75/'Data Sheet'!D$75 -> 1 | F39: ='Data Sheet'!E75/'Data Sheet'!E$75 -> 1 | G39: ='Data Sheet'!F75/'Data Sheet'!F$75 -> 1 | H39: ='Data Sheet'!G75/'Data Sheet'!G$75 -> 1 | I39: ='Data Sheet'!H75/'Data Sheet'!H$75 -> 1 | J39: ='Data Sheet'!I75/'Data Sheet'!I$75 -> 1 | ... L39: ='Data Sheet'!K75/'Data Sheet'!K$75 -> 1
B40: ='Data Sheet'!A62 -> Net Block | C40: ='Data Sheet'!B62/'Data Sheet'!B$75 -> 0.2202393 | D40: ='Data Sheet'!C62/'Data Sheet'!C$75 -> 0.28135744 | E40: ='Data Sheet'!D62/'Data Sheet'!D$75 -> 0.25349905 | F40: ='Data Sheet'!E62/'Data Sheet'!E$75 -> 0.25310001 | G40: ='Data Sheet'!F62/'Data Sheet'!F$75 -> 0.27187019 | H40: ='Data Sheet'!G62/'Data Sheet'!G$75 -> 0.74837067 | I40: ='Data Sheet'!H62/'Data Sheet'!H$75 -> 0.73005134 | J40: ='Data Sheet'!I62/'Data Sheet'!I$75 -> 0.72085608 | ... L40: ='Data Sheet'!K62/'Data Sheet'!K$75 -> 0.6803526
B41: ='Data Sheet'!A63 -> Capital Work in Progress | C41: ='Data Sheet'!B63/'Data Sheet'!B$75 -> 0.027580612 | D41: ='Data Sheet'!C63/'Data Sheet'!C$75 -> 0.014580415 | E41: ='Data Sheet'!D63/'Data Sheet'!D$75 -> 0.02580898 | F41: ='Data Sheet'!E63/'Data Sheet'!E$75 -> 0.021793977 | G41: ='Data Sheet'!F63/'Data Sheet'!F$75 -> 0.029623381 | H41: ='Data Sheet'!G63/'Data Sheet'!G$75 -> 0.01083794 | I41: ='Data Sheet'!H63/'Data Sheet'!H$75 -> 0.018622529 | J41: ='Data Sheet'!I63/'Data Sheet'!I$75 -> 0.01549051 | ... L41: ='Data Sheet'!K63/'Data Sheet'!K$75 -> 0.012634136
B42: ='Data Sheet'!A64 -> Investments | C42: ='Data Sheet'!B64/'Data Sheet'!B$75 -> 0.17521801 | D42: ='Data Sheet'!C64/'Data Sheet'!C$75 -> 0.24156373 | E42: ='Data Sheet'!D64/'Data Sheet'!D$75 -> 0.16084425 | F42: ='Data Sheet'!E64/'Data Sheet'!E$75 -> 0.14579419 | G42: ='Data Sheet'!F64/'Data Sheet'!F$75 -> 0.062273607 | H42: ='Data Sheet'!G64/'Data Sheet'!G$75 -> 0.039409369 | I42: ='Data Sheet'!H64/'Data Sheet'!H$75 -> 0.049939012 | J42: ='Data Sheet'!I64/'Data Sheet'!I$75 -> 0.039437853 | ... L42: ='Data Sheet'!K64/'Data Sheet'!K$75 -> 0.047706698
B43: ='Data Sheet'!A65 -> Other Assets | C43: ='Data Sheet'!B74/'Data Sheet'!B$75 -> 0.10383289 | D43: ='Data Sheet'!C74/'Data Sheet'!C$75 -> 0.11524258 | E43: ='Data Sheet'!D74/'Data Sheet'!D$75 -> 0.15071101 | F43: ='Data Sheet'!E74/'Data Sheet'!E$75 -> 0.14198293 | G43: ='Data Sheet'!F74/'Data Sheet'!F$75 -> 0.18821019 | H43: ='Data Sheet'!G74/'Data Sheet'!G$75 -> 0.058699447 | I43: ='Data Sheet'!H74/'Data Sheet'!H$75 -> 0.057030607 | J43: ='Data Sheet'!I74/'Data Sheet'!I$75 -> 0.059895726 | ... L43: ='Data Sheet'!K74/'Data Sheet'!K$75 -> 0.061618021
B44: ='Data Sheet'!A67 -> Receivables | C44: ='Data Sheet'!B67/'Data Sheet'!B$75 -> 0.085445819 | D44: ='Data Sheet'!C67/'Data Sheet'!C$75 -> 0.06908188 | E44: ='Data Sheet'!D67/'Data Sheet'!D$75 -> 0.073340052 | F44: ='Data Sheet'!E67/'Data Sheet'!E$75 -> 0.09748242 | G44: ='Data Sheet'!F67/'Data Sheet'!F$75 -> 0.057013844 | H44: ='Data Sheet'!G67/'Data Sheet'!G$75 -> 0.025574629 | I44: ='Data Sheet'!H67/'Data Sheet'!H$75 -> 0.031713613 | J44: ='Data Sheet'!I67/'Data Sheet'!I$75 -> 0.04213364 | ... L44: ='Data Sheet'!K67/'Data Sheet'!K$75 -> 0.047819391
B45: ='Data Sheet'!A68 -> Inventory | C45: ='Data Sheet'!B68/'Data Sheet'!B$75 -> 0.18427635 | D45: ='Data Sheet'!C68/'Data Sheet'!C$75 -> 0.1617853 | E45: ='Data Sheet'!D68/'Data Sheet'!D$75 -> 0.14068973 | F45: ='Data Sheet'!E68/'Data Sheet'!E$75 -> 0.13817167 | G45: ='Data Sheet'!F68/'Data Sheet'!F$75 -> 0.13729966 | H45: ='Data Sheet'!G68/'Data Sheet'!G$75 -> 0.052065755 | I45: ='Data Sheet'!H68/'Data Sheet'!H$75 -> 0.058094347 | J45: ='Data Sheet'!I68/'Data Sheet'!I$75 -> 0.058171518 | ... L45: ='Data Sheet'!K68/'Data Sheet'!K$75 -> 0.055282171
B46: ='Data Sheet'!A69 -> Cash & Bank | C46: ='Data Sheet'!B69/'Data Sheet'!B$75 -> 0.20340702 | D46: ='Data Sheet'!C69/'Data Sheet'!C$75 -> 0.11638864 | E46: ='Data Sheet'!D69/'Data Sheet'!D$75 -> 0.19510693 | F46: ='Data Sheet'!E69/'Data Sheet'!E$75 -> 0.20167481 | G46: ='Data Sheet'!F69/'Data Sheet'!F$75 -> 0.25370913 | H46: ='Data Sheet'!G69/'Data Sheet'!G$75 -> 0.065042188 | I46: ='Data Sheet'!H69/'Data Sheet'!H$75 -> 0.054548549 | J46: ='Data Sheet'!I69/'Data Sheet'!I$75 -> 0.064014669 | ... L46: ='Data Sheet'!K69/'Data Sheet'!K$75 -> 0.09458698

Sheet Ratio Analysis
B3: ='Dupont Analysis'!B3 -> HINDUSTAN UNILEVER LTD
B4: ='Dupont Analysis'!B4 -> (HINDUNILVR | BSE Code: 500696)
B6: Ratio Analysis
B8: ="Ratio Analysis -"&'Data Sheet'!B1 -> Ratio Analysis -HINDUSTAN UNILEVER LTD
B9: Years | C9: ='Data Sheet'!B16 -> 42460 | D9: ='Data Sheet'!C16 -> 42825 | E9: ='Data Sheet'!D16 -> 43190 | F9: ='Data Sheet'!E16 -> 43555 | G9: ='Data Sheet'!F16 -> 43921 | H9: ='Data Sheet'!G16 -> 44286 | I9: ='Data Sheet'!H16 -> 44651 | J9: ='Data Sheet'!I16 -> 45016 | ... L9: ='Data Sheet'!K16 -> 45747 | M9: Trend | N9: Mean | O9: Median
B11: Sales Growth | C11: =IFERROR(HistoricalFS!C13,0) -> - | D11: =IFERROR(HistoricalFS!D13,0) -> 0.030323743 | E11: =IFERROR(HistoricalFS!E13,0) -> 0.071859357 | F11: =IFERROR(HistoricalFS!F13,0) -> 0.10592207 | G11: =IFERROR(HistoricalFS!G13,0) -> 0.012032562 | H11: =IFERROR(HistoricalFS!H13,0) -> 0.18211296 | I11: =IFERROR(HistoricalFS!I13,0) -> 0.11520796 | J11: =IFERROR(HistoricalFS!J13,0) -> 0.15509286 | ... L11: =IFERROR(HistoricalFS!L13,0) -> 0.019791263 | N11: =IFERROR(AVERAGE(D11:L11),0) -> 0.07934068 | O11: =IFERROR(MEDIAN(C11:L11),0) -> 0.071859357
B12: EBIDTA Growth | D12: =IFERROR(HistoricalFS!D24/HistoricalFS!C24-1,0) -> 0.07072758 | E12: =IFERROR(HistoricalFS!E24/HistoricalFS!D24-1,0) -> 0.18505057 | F12: =IFERROR(HistoricalFS!F24/HistoricalFS!E24-1,0) -> 0.18415789 | G12: =IFERROR(HistoricalFS!G24/HistoricalFS!F24-1,0) -> 0.11047297 | H12: =IFERROR(HistoricalFS!H24/HistoricalFS!G24-1,0) -> 0.17898793 | I12: =IFERROR(HistoricalFS!I24/HistoricalFS!H24-1,0) -> 0.10588336 | J12: =IFERROR(HistoricalFS!J24/HistoricalFS!I24-1,0) -> 0.10033445 | K12: =IFERROR(HistoricalFS!K24/HistoricalFS!J24-1,0) -> 0.036191419 | L12: =IFERROR(HistoricalFS!L24/HistoricalFS!K24-1,0) -> 0.012552016 | N12: =IFERROR(AVERAGE(D12:L12),0) -> 0.10937313 | O12: =IFERROR(MEDIAN(C12:L12),0) -> 0.10588336
B13: EBIT Growth | D13: =IFERROR(SUM(HistoricalFS!D33,HistoricalFS!D27)/SUM(HistoricalFS!C33,HistoricalFS!C27)-1,0) -> 0.061004139 | E13: =IFERROR(SUM(HistoricalFS!E33,HistoricalFS!E27)/SUM(HistoricalFS!D33,HistoricalFS!D27)-1,0) -> 0.18368385 | F13: =IFERROR(SUM(HistoricalFS!F33,HistoricalFS!F27)/SUM(HistoricalFS!E33,HistoricalFS!E27)-1,0) -> 0.19143144 | G13: =IFERROR(SUM(HistoricalFS!G33,HistoricalFS!G27)/SUM(HistoricalFS!F33,HistoricalFS!F27)-1,0) -> 0.065423933 | H13: =IFERROR(SUM(HistoricalFS!H33,HistoricalFS!H27)/SUM(HistoricalFS!G33,HistoricalFS!G27)-1,0) -> 0.19110509 | I13: =IFERROR(SUM(HistoricalFS!I33,HistoricalFS!I27)/SUM(HistoricalFS!H33,HistoricalFS!H27)-1,0) -> 0.11504928 | J13: =IFERROR(SUM(HistoricalFS!J33,HistoricalFS!J27)/SUM(HistoricalFS!I33,HistoricalFS!I27)-1,0) -> 0.10572837 | K13: =IFERROR(SUM(HistoricalFS!K33,HistoricalFS!K27)/SUM(HistoricalFS!J33,HistoricalFS!J27)-1,0) -> 0.033282091 | L13: =IFERROR(SUM(HistoricalFS!L33,HistoricalFS!L27)/SUM(HistoricalFS!K33,HistoricalFS!K27)-1,0) -> 0.0033474671 | N13: =IFERROR(AVERAGE(D13:L13),0) -> 0.10556174 | O13: =IFERROR(MEDIAN(C13:L13),0) -> 0.10572837
B14: Net Profit Growth | D14: =IFERROR(HistoricalFS!D39/HistoricalFS!C39-1,0) -> 0.059754434 | E14: =IFERROR(HistoricalFS!E39/HistoricalFS!D39-1,0) -> 0.25489186 | F14: =IFERROR(HistoricalFS!F39/HistoricalFS!E39-1,0) -> 0.17726713 | G14: =IFERROR(HistoricalFS!G39/HistoricalFS!F39-1,0) -> 0.10352039 | H14: =IFERROR(HistoricalFS!H39/HistoricalFS!G39-1,0) -> 0.23641819 | I14: =IFERROR(HistoricalFS!I39/HistoricalFS!H39-1,0) -> 0.10780432 | J14: =IFERROR(HistoricalFS!J39/HistoricalFS!I39-1,0) -> 0.11783697 | K14: =IFERROR(HistoricalFS!K39/HistoricalFS!J39-1,0) -> -0.023723569 | L14: =IFERROR(HistoricalFS!L39/HistoricalFS!K39-1,0) -> -0.012255679 | N14: =IFERROR(AVERAGE(D14:L14),0) -> 0.11350156 | O14: =IFERROR(MEDIAN(C14:L14),0) -> 0.10780432
B15: Dividend Growth | D15: =IFERROR(HistoricalFS!D47/HistoricalFS!C47-1,0) -> 0.062303632 | E15: =IFERROR(HistoricalFS!E47/HistoricalFS!D47-1,0) -> 0.17636188 | F15: =IFERROR(HistoricalFS!F47/HistoricalFS!E47-1,0) -> 0.099898369 | G15: =IFERROR(HistoricalFS!G47/HistoricalFS!F47-1,0) -> 0.13631114 | H15: =IFERROR(HistoricalFS!H47/HistoricalFS!G47-1,0) -> 0.6238764 | I15: =IFERROR(HistoricalFS!I47/HistoricalFS!H47-1,0) -> -0.16049383 | J15: =IFERROR(HistoricalFS!J47/HistoricalFS!I47-1,0) -> 0.14705882 | K15: =IFERROR(HistoricalFS!K47/HistoricalFS!J47-1,0) -> 0.076923077 | L15: =IFERROR(HistoricalFS!L47/HistoricalFS!K47-1,0) -> 0.26190476 | N15: =IFERROR(AVERAGE(D15:L15),0) -> 0.15823825 | O15: =IFERROR(MEDIAN(C15:L15),0) -> 0.13631114
B17: Gross Margin | C17: =IFERROR(HistoricalFS!C19,0) -> 0.43385323 | D17: =IFERROR(HistoricalFS!D19,0) -> 0.43685544 | E17: =IFERROR(HistoricalFS!E19,0) -> 0.45663244 | F17: =IFERROR(HistoricalFS!F19,0) -> 0.46372424 | G17: =IFERROR(HistoricalFS!G19,0) -> 0.48183898 | H17: =IFERROR(HistoricalFS!H19,0) -> 0.46200136 | I17: =IFERROR(HistoricalFS!I19,0) -> 0.44579186 | J17: =IFERROR(HistoricalFS!J19,0) -> 0.41596236 | ... L17: =IFERROR(HistoricalFS!L19,0) -> 0.45297128 | N17: =IFERROR(AVERAGE(C17:L17),0) -> 0.45059612 | O17: =IFERROR(MEDIAN(C17:L17),0) -> 0.45465063
B18: EBIDTA Margin | C18: =IFERROR(HistoricalFS!C25,0) -> 0.18362021 | D18: =IFERROR(HistoricalFS!D25,0) -> 0.19082082 | E18: =IFERROR(HistoricalFS!E25,0) -> 0.21097201 | F18: =IFERROR(HistoricalFS!F25,0) -> 0.22589672 | G18: =IFERROR(HistoricalFS!G25,0) -> 0.24786969 | H18: =IFERROR(HistoricalFS!H25,0) -> 0.24721443 | I18: =IFERROR(HistoricalFS!I25,0) -> 0.24514739 | J18: =IFERROR(HistoricalFS!J25,0) -> 0.23352592 | ... L18: =IFERROR(HistoricalFS!L25,0) -> 0.23515153 | N18: =IFERROR(AVERAGE(C18:L18),0) -> 0.22570515 | O18: =IFERROR(MEDIAN(C18:L18),0) -> 0.23433873
B19: EBIT Margin | C19: =IFERROR((HistoricalFS!C33+HistoricalFS!C27)/(HistoricalFS!C12),0) -> 0.17265271 | D19: =IFERROR((HistoricalFS!D33+HistoricalFS!D27)/(HistoricalFS!D12),0) -> 0.17779386 | E19: =IFERROR((HistoricalFS!E33+HistoricalFS!E27)/(HistoricalFS!E12),0) -> 0.19634266 | F19: =IFERROR((HistoricalFS!F33+HistoricalFS!F27)/(HistoricalFS!F12),0) -> 0.21152379 | G19: =IFERROR((HistoricalFS!G33+HistoricalFS!G27)/(HistoricalFS!G12),0) -> 0.22268306 | H19: =IFERROR((HistoricalFS!H33+HistoricalFS!H27)/(HistoricalFS!H12),0) -> 0.22437697 | I19: =IFERROR((HistoricalFS!I33+HistoricalFS!I27)/(HistoricalFS!I12),0) -> 0.22434504 | J19: =IFERROR((HistoricalFS!J33+HistoricalFS!J27)/(HistoricalFS!J12),0) -> 0.21475735 | ... L19: =IFERROR((HistoricalFS!L33+HistoricalFS!L27)/(HistoricalFS!L12),0) -> 0.21368483 | N19: =IFERROR(AVERAGE(C19:L19),0) -> 0.20753471 | O19: =IFERROR(MEDIAN(C19:L19),0) -> 0.21422109
B20: EBT Margin | C20: =IFERROR(HistoricalFS!C34,0) -> 0.17212453 | D20: =IFERROR(HistoricalFS!D34,0) -> 0.17673844 | E20: =IFERROR(HistoricalFS!E34,0) -> 0.1956112 | F20: =IFERROR(HistoricalFS!F34,0) -> 0.2106843 | G20: =IFERROR(HistoricalFS!G34,0) -> 0.21971696 | H20: =IFERROR(HistoricalFS!H34,0) -> 0.22188909 | I20: =IFERROR(HistoricalFS!I34,0) -> 0.22232391 | J20: =IFERROR(HistoricalFS!J34,0) -> 0.21287554 | ... L20: =IFERROR(HistoricalFS!L34,0) -> 0.20742701 | N20: =IFERROR(AVERAGE(C20:L20),0) -> 0.20511817 | O20: =IFERROR(MEDIAN(C20:L20),0) -> 0.21123753
B21: Net Profit Margin | C21: =IFERROR(HistoricalFS!C40,0) -> 0.11386938 | D21: =IFERROR(HistoricalFS!D40,0) -> 0.11712201 | E21: =IFERROR(HistoricalFS!E40,0) -> 0.13712196 | F21: =IFERROR(HistoricalFS!F40,0) -> 0.14596795 | G21: =IFERROR(HistoricalFS!G40,0) -> 0.15916346 | H21: =IFERROR(HistoricalFS!H40,0) -> 0.16647529 | I21: =IFERROR(HistoricalFS!I40,0) -> 0.16537009 | J21: =IFERROR(HistoricalFS!J40,0) -> 0.16003632 | ... L21: =IFERROR(HistoricalFS!L40,0) -> 0.14811236 | N21: =IFERROR(AVERAGE(C21:L21),0) -> 0.14661566 | O21: =IFERROR(MEDIAN(C21:L21),0) -> 0.15051508
B23: SalesExpenses%Sales | C23: =IFERROR(HistoricalFS!C22,0) -> 0.25023302 | D23: =IFERROR(HistoricalFS!D22,0) -> 0.24603462 | E23: =IFERROR(HistoricalFS!E22,0) -> 0.24566043 | F23: =IFERROR(HistoricalFS!F22,0) -> 0.23782752 | G23: =IFERROR(HistoricalFS!G22,0) -> 0.23396928 | H23: =IFERROR(HistoricalFS!H22,0) -> 0.21478694 | I23: =IFERROR(HistoricalFS!I22,0) -> 0.20064447 | J23: =IFERROR(HistoricalFS!J22,0) -> 0.18243645 | ... L23: =IFERROR(HistoricalFS!L22,0) -> 0.21781974 | N23: =IFERROR(AVERAGE(C23:L23),0) -> 0.22489097 | O23: =IFERROR(MEDIAN(C23:L23),0) -> 0.22673325
B24: Depreciation%Sales | C24: =IFERROR(HistoricalFS!C31,0) -> 0.010967501 | D24: =IFERROR(HistoricalFS!D31,0) -> 0.013026959 | E24: =IFERROR(HistoricalFS!E31,0) -> 0.014629343 | F24: =IFERROR(HistoricalFS!F31,0) -> 0.014372933 | G24: =IFERROR(HistoricalFS!G31,0) -> 0.025186638 | H24: =IFERROR(HistoricalFS!H31,0) -> 0.022837459 | I24: =IFERROR(HistoricalFS!I31,0) -> 0.020802349 | J24: =IFERROR(HistoricalFS!J31,0) -> 0.01876857 | ... L24: =IFERROR(HistoricalFS!L31,0) -> 0.021466707 | N24: =IFERROR(AVERAGE(C24:L24),0) -> 0.018170432 | O24: =IFERROR(MEDIAN(C24:L24),0) -> 0.019207214
B25: OperatingIncome%Sales | C25: =C19 -> 0.17265271 | D25: =D19 -> 0.17779386 | E25: =E19 -> 0.19634266 | F25: =F19 -> 0.21152379 | G25: =G19 -> 0.22268306 | H25: =H19 -> 0.22437697 | I25: =I19 -> 0.22434504 | J25: =J19 -> 0.21475735 | ... L25: =L19 -> 0.21368483 | N25: =IFERROR(AVERAGE(C25:L25),0) -> 0.20753471 | O25: =IFERROR(MEDIAN(C25:L25),0) -> 0.21422109
B27: Return On Captial Employed | C27: =IFERROR((HistoricalFS!C24-HistoricalFS!C30)/SUM(HistoricalFS!C53:C55),0) -> 0.82325926 | D27: =IFERROR((HistoricalFS!D24-HistoricalFS!D30)/SUM(HistoricalFS!D53:D55),0) -> 0.83976642 | E27: =IFERROR((HistoricalFS!E24-HistoricalFS!E30)/SUM(HistoricalFS!E53:E55),0) -> 0.95852218 | F27: =IFERROR((HistoricalFS!F24-HistoricalFS!F30)/SUM(HistoricalFS!F53:F55),0) -> 1.0438112 | G27: =IFERROR((HistoricalFS!G24-HistoricalFS!G30)/SUM(HistoricalFS!G53:G55),0) -> 1.0765585 | H27: =IFERROR((HistoricalFS!H24-HistoricalFS!H30)/SUM(HistoricalFS!H53:H55),0) -> 0.22133658 | I27: =IFERROR((HistoricalFS!I24-HistoricalFS!I30)/SUM(HistoricalFS!I53:I55),0) -> 0.23483155 | J27: =IFERROR((HistoricalFS!J24-HistoricalFS!J30)/SUM(HistoricalFS!J53:J55),0) -> 0.25250859 | ... L27: =IFERROR((HistoricalFS!L24-HistoricalFS!L30)/SUM(HistoricalFS!L53:L55),0) -> 0.26421156 | N27: =IFERROR(AVERAGE(C27:L27),0) -> 0.59698815 | O27: =IFERROR(MEDIAN(C27:L27),0) -> 0.54373541
B28: Retained Earnings | C28: =IFERROR(HistoricalFS!C50,0) -> 0.057025921 | D28: =IFERROR(HistoricalFS!D50,0) -> 0.054582904 | E28: =IFERROR(HistoricalFS!E50,0) -> 0.11366434 | F28: =IFERROR(HistoricalFS!F50,0) -> 0.17183688 | G28: =IFERROR(HistoricalFS!G50,0) -> 0.14718888 | H28: =IFERROR(HistoricalFS!H50,0) -> -0.2156725 | I28: =IFERROR(HistoricalFS!I50,0) -> 0.078750144 | J28: =IFERROR(HistoricalFS!J50,0) -> 0.054667354 | ... L28: =IFERROR(HistoricalFS!L50,0) -> -0.33222805 | N28: =IFERROR(AVERAGE(C28:L28),0) -> 0.0087026655 | O28: =IFERROR(MEDIAN(C28:L28),0) -> 0.055846638
B29: Return on Equity | C29: =IFERROR(HistoricalFS!C39/SUM(HistoricalFS!C53:C54),0) -> 0.55758406 | D29: =IFERROR(HistoricalFS!D39/SUM(HistoricalFS!D53:D54),0) -> 0.57591934 | E29: =IFERROR(HistoricalFS!E39/SUM(HistoricalFS!E53:E54),0) -> 0.66941354 | F29: =IFERROR(HistoricalFS!F39/SUM(HistoricalFS!F53:F54),0) -> 0.72937587 | G29: =IFERROR(HistoricalFS!G39/SUM(HistoricalFS!G53:G54),0) -> 0.76947381 | H29: =IFERROR(HistoricalFS!H39/SUM(HistoricalFS!H53:H54),0) -> 0.16421949 | I29: =IFERROR(HistoricalFS!I39/SUM(HistoricalFS!I53:I54),0) -> 0.17677993 | J29: =IFERROR(HistoricalFS!J39/SUM(HistoricalFS!J53:J54),0) -> 0.19272821 | ... L29: =IFERROR(HistoricalFS!L39/SUM(HistoricalFS!L53:L54),0) -> 0.18924335 | N29: =IFERROR(AVERAGE(C29:L29),0) -> 0.42095359 | O29: =IFERROR(MEDIAN(C29:L29),0) -> 0.37515613
B30: Self Sustained Growth Rate | C30: =IFERROR(C29*C28,0) -> 0.031796744 | D30: =IFERROR(D29*D28,0) -> 0.03143535 | E30: =IFERROR(E29*E28,0) -> 0.076088449 | F30: =IFERROR(F29*F28,0) -> 0.12533367 | G30: =IFERROR(G29*G28,0) -> 0.11325799 | H30: =IFERROR(H29*H28,0) -> -0.035417628 | I30: =IFERROR(I29*I28,0) -> 0.013921445 | J30: =IFERROR(J29*J28,0) -> 0.010535941 | ... L30: =IFERROR(L29*L28,0) -> -0.062871949 | N30: =IFERROR(AVERAGE(C30:L30),0) -> 0.029617264 | O30: =IFERROR(MEDIAN(C30:L30),0) -> 0.022678397
B31: Interest Coverage Ratio | C31: =IFERROR((HistoricalFS!C24-HistoricalFS!C30)/HistoricalFS!C27,0) -> 326.88235 | D31: =IFERROR((HistoricalFS!D24-HistoricalFS!D30)/HistoricalFS!D27,0) -> 168.45714 | E31: =IFERROR((HistoricalFS!E24-HistoricalFS!E30)/HistoricalFS!E27,0) -> 268.42308 | F31: =IFERROR((HistoricalFS!F24-HistoricalFS!F30)/HistoricalFS!F27,0) -> 251.9697 | G31: =IFERROR((HistoricalFS!G24-HistoricalFS!G30)/HistoricalFS!G27,0) -> 75.076271 | H31: =IFERROR((HistoricalFS!H24-HistoricalFS!H30)/HistoricalFS!H27,0) -> 90.188034 | I31: =IFERROR((HistoricalFS!I24-HistoricalFS!I30)/HistoricalFS!I27,0) -> 111 | J31: =IFERROR((HistoricalFS!J24-HistoricalFS!J30)/HistoricalFS!J27,0) -> 114.12281 | ... L31: =IFERROR((HistoricalFS!L24-HistoricalFS!L30)/HistoricalFS!L27,0) -> 34.146835 | N31: =IFERROR(AVERAGE(C31:L31),0) -> 148.05147 | O31: =IFERROR(MEDIAN(C31:L31),0) -> 112.5614
B33: Debtor Turnover Ratio | C33: =IFERROR(HistoricalFS!C12/HistoricalFS!C65,0) -> 25.463608 | D33: =IFERROR(HistoricalFS!D12/HistoricalFS!D65,0) -> 30.564055 | E33: =IFERROR(HistoricalFS!E12/HistoricalFS!E65,0) -> 27.133588 | F33: =IFERROR(HistoricalFS!F12/HistoricalFS!F65,0) -> 21.646476 | G33: =IFERROR(HistoricalFS!G12/HistoricalFS!G65,0) -> 34.624021 | H33: =IFERROR(HistoricalFS!H12/HistoricalFS!H65,0) -> 26.750853 | I33: =IFERROR(HistoricalFS!I12/HistoricalFS!I65,0) -> 23.455277 | J33: =IFERROR(HistoricalFS!J12/HistoricalFS!J65,0) -> 19.675219 | ... L33: =IFERROR(HistoricalFS!L12/HistoricalFS!L65,0) -> 16.528149 | N33: =IFERROR(AVERAGE(C33:L33),0) -> 24.64939 | O33: =IFERROR(MEDIAN(C33:L33),0) -> 24.459442
